[2023-09-25T12:47:40.155-0300] {taskinstance.py:1103} INFO - Dependencies all met for dep_context=non-requeueable deps ti=<TaskInstance: test_1.task0 manual__2023-09-25T12:47:29-03:00 [queued]>
[2023-09-25T12:47:40.165-0300] {taskinstance.py:1103} INFO - Dependencies all met for dep_context=requeueable deps ti=<TaskInstance: test_1.task0 manual__2023-09-25T12:47:29-03:00 [queued]>
[2023-09-25T12:47:40.166-0300] {taskinstance.py:1308} INFO - Starting attempt 1 of 2
[2023-09-25T12:47:40.206-0300] {taskinstance.py:1327} INFO - Executing <Task(PythonOperator): task0> on 2023-09-25 15:47:29+00:00
[2023-09-25T12:47:40.210-0300] {standard_task_runner.py:57} INFO - Started process 7665 to run task
[2023-09-25T12:47:40.214-0300] {standard_task_runner.py:84} INFO - Running: ['airflow', 'tasks', 'run', 'test_1', 'task0', 'manual__2023-09-25T12:47:29-03:00', '--job-id', '24', '--raw', '--subdir', 'DAGS_FOLDER/test1.py', '--cfg-path', '/tmp/tmpoxfhctr2']
[2023-09-25T12:47:40.217-0300] {standard_task_runner.py:85} INFO - Job 24: Subtask task0
[2023-09-25T12:47:40.287-0300] {task_command.py:410} INFO - Running <TaskInstance: test_1.task0 manual__2023-09-25T12:47:29-03:00 [running]> on host mkm
[2023-09-25T12:47:40.410-0300] {taskinstance.py:1545} INFO - Exporting env vars: AIRFLOW_CTX_DAG_EMAIL='emilianoemanuel2850@gmail.com' AIRFLOW_CTX_DAG_OWNER='airflow' AIRFLOW_CTX_DAG_ID='test_1' AIRFLOW_CTX_TASK_ID='task0' AIRFLOW_CTX_EXECUTION_DATE='2023-09-25T15:47:29+00:00' AIRFLOW_CTX_TRY_NUMBER='1' AIRFLOW_CTX_DAG_RUN_ID='manual__2023-09-25T12:47:29-03:00'
[2023-09-25T12:47:40.418-0300] {taskinstance.py:1824} ERROR - Task failed with exception
Traceback (most recent call last):
  File "/home/mkm/programing/Brain_Wave_Data_Pipeline/env/lib/python3.11/site-packages/airflow/operators/python.py", line 181, in execute
    return_value = self.execute_callable()
                   ^^^^^^^^^^^^^^^^^^^^^^^
  File "/home/mkm/programing/Brain_Wave_Data_Pipeline/env/lib/python3.11/site-packages/airflow/operators/python.py", line 198, in execute_callable
    return self.python_callable(*self.op_args, **self.op_kwargs)
           ^^^^^^^^^^^^^^^^^^^^^^^^^^^^^^^^^^^^^^^^^^^^^^^^^^^^^
  File "/home/mkm/programing/Brain_Wave_Data_Pipeline/airflow/dags/test1.py", line 42, in task0_func
    raise AirflowFailException("Ese commit es invalido para desplegar....")
airflow.exceptions.AirflowFailException: Ese commit es invalido para desplegar....
[2023-09-25T12:47:40.431-0300] {taskinstance.py:1345} INFO - Immediate failure requested. Marking task as FAILED. dag_id=test_1, task_id=task0, execution_date=20230925T154729, start_date=20230925T154740, end_date=20230925T154740
[2023-09-25T12:47:40.480-0300] {standard_task_runner.py:104} ERROR - Failed to execute job 24 for task task0 (Ese commit es invalido para desplegar....; 7665)
[2023-09-25T12:47:40.515-0300] {local_task_job_runner.py:225} INFO - Task exited with return code 1
[2023-09-25T12:47:40.538-0300] {taskinstance.py:2653} INFO - 0 downstream tasks scheduled from follow-on schedule check
