[2023-09-25T17:15:10.035-0300] {taskinstance.py:1103} INFO - Dependencies all met for dep_context=non-requeueable deps ti=<TaskInstance: test_1.task0 manual__2023-09-25T17:14:09-03:00 [queued]>
[2023-09-25T17:15:10.062-0300] {taskinstance.py:1103} INFO - Dependencies all met for dep_context=requeueable deps ti=<TaskInstance: test_1.task0 manual__2023-09-25T17:14:09-03:00 [queued]>
[2023-09-25T17:15:10.063-0300] {taskinstance.py:1308} INFO - Starting attempt 1 of 2
[2023-09-25T17:15:10.102-0300] {taskinstance.py:1327} INFO - Executing <Task(PythonOperator): task0> on 2023-09-25 20:14:09+00:00
[2023-09-25T17:15:10.108-0300] {standard_task_runner.py:57} INFO - Started process 7319 to run task
[2023-09-25T17:15:10.114-0300] {standard_task_runner.py:84} INFO - Running: ['airflow', 'tasks', 'run', 'test_1', 'task0', 'manual__2023-09-25T17:14:09-03:00', '--job-id', '14', '--raw', '--subdir', 'DAGS_FOLDER/test1.py', '--cfg-path', '/tmp/tmpeiaxd6ol']
[2023-09-25T17:15:10.116-0300] {standard_task_runner.py:85} INFO - Job 14: Subtask task0
[2023-09-25T17:15:10.195-0300] {task_command.py:410} INFO - Running <TaskInstance: test_1.task0 manual__2023-09-25T17:14:09-03:00 [running]> on host mkm
[2023-09-25T17:15:10.344-0300] {taskinstance.py:1545} INFO - Exporting env vars: AIRFLOW_CTX_DAG_EMAIL='emilianoemanuel2850@gmail.com' AIRFLOW_CTX_DAG_OWNER='airflow' AIRFLOW_CTX_DAG_ID='test_1' AIRFLOW_CTX_TASK_ID='task0' AIRFLOW_CTX_EXECUTION_DATE='2023-09-25T20:14:09+00:00' AIRFLOW_CTX_TRY_NUMBER='1' AIRFLOW_CTX_DAG_RUN_ID='manual__2023-09-25T17:14:09-03:00'
[2023-09-25T17:15:10.346-0300] {taskinstance.py:1824} ERROR - Task failed with exception
Traceback (most recent call last):
  File "/home/mkm/programing/Brain_Wave_Data_Pipeline/env/lib/python3.11/site-packages/airflow/operators/python.py", line 181, in execute
    return_value = self.execute_callable()
                   ^^^^^^^^^^^^^^^^^^^^^^^
  File "/home/mkm/programing/Brain_Wave_Data_Pipeline/env/lib/python3.11/site-packages/airflow/operators/python.py", line 198, in execute_callable
    return self.python_callable(*self.op_args, **self.op_kwargs)
           ^^^^^^^^^^^^^^^^^^^^^^^^^^^^^^^^^^^^^^^^^^^^^^^^^^^^^
  File "/home/mkm/programing/Brain_Wave_Data_Pipeline/airflow/dags/test1.py", line 42, in task0_func
    raise AirflowFailException("Ese commit es invalido para desplegar....")
airflow.exceptions.AirflowFailException: Ese commit es invalido para desplegar....
[2023-09-25T17:15:10.358-0300] {taskinstance.py:1345} INFO - Immediate failure requested. Marking task as FAILED. dag_id=test_1, task_id=task0, execution_date=20230925T201409, start_date=20230925T201510, end_date=20230925T201510
[2023-09-25T17:15:10.394-0300] {standard_task_runner.py:104} ERROR - Failed to execute job 14 for task task0 (Ese commit es invalido para desplegar....; 7319)
[2023-09-25T17:15:10.444-0300] {local_task_job_runner.py:225} INFO - Task exited with return code 1
[2023-09-25T17:15:10.502-0300] {taskinstance.py:2653} INFO - 0 downstream tasks scheduled from follow-on schedule check
